{"name": "test_mp_login[13812345678-246810-Xeo]", "status": "broken", "statusDetails": {"message": "FileNotFoundError: [Errno 2] No such file or directory: '../image/err.png'", "trace": "self = <scripts.test01_mp_login.TestMpLogin object at 0x000001CD40F6C250>\nusername = '13812345678', code = '246810', expect_result = 'Xeo'\n\n    @pytest.mark.parametrize(\"username,code,expect_result\", read_yaml(\"mp_login.yaml\"))\n    def test_mp_login(self, username, code, expect_result):\n        print(username+\"---------\"+code)\n        # 调用登录业务方法\n        self.mp.page_mp_login(username, code)\n        try:\n            # 断言\n>           assert expect_result == self.mp.page_get_nickname()\nE           AssertionError: assert 'Xeo' == 'Xeon'\nE             - Xeon\nE             ?    -\nE             + Xeo\n\nscripts\\test01_mp_login.py:28: AssertionError\n\nDuring handling of the above exception, another exception occurred:\n\nself = <scripts.test01_mp_login.TestMpLogin object at 0x000001CD40F6C250>\nusername = '13812345678', code = '246810', expect_result = 'Xeo'\n\n    @pytest.mark.parametrize(\"username,code,expect_result\", read_yaml(\"mp_login.yaml\"))\n    def test_mp_login(self, username, code, expect_result):\n        print(username+\"---------\"+code)\n        # 调用登录业务方法\n        self.mp.page_mp_login(username, code)\n        try:\n            # 断言\n            assert expect_result == self.mp.page_get_nickname()\n            print(self.mp.page_get_nickname())\n        except Exception as e:\n            # 打印异常\n            print(\"异常是：\",e)\n            # 截图\n>           self.mp.base_get_image()\n\nscripts\\test01_mp_login.py:34: \n_ _ _ _ _ _ _ _ _ _ _ _ _ _ _ _ _ _ _ _ _ _ _ _ _ _ _ _ _ _ _ _ _ _ _ _ _ _ _ _ _ _ _ _ _ \nbase\\base.py:41: in base_get_image\n    self.__base_write_img()\n_ _ _ _ _ _ _ _ _ _ _ _ _ _ _ _ _ _ _ _ _ _ _ _ _ _ _ _ _ _ _ _ _ _ _ _ _ _ _ _ _ _ _ _ _ \n\nself = <page.page_mp_login.PageMpLogin object at 0x000001CD41253EE0>\n\n    def __base_write_img(self):\n         # 获取图片写入文件流\n>           with open(\"../image/err.png\",\"rb\") as f:\nE           FileNotFoundError: [Errno 2] No such file or directory: '../image/err.png'\n\nbase\\base.py:46: FileNotFoundError"}, "parameters": [{"name": "username", "value": "'13812345678'"}, {"name": "code", "value": "'246810'"}, {"name": "expect_result", "value": "'Xeo'"}], "start": 1604245577894, "stop": 1604245580466, "uuid": "291820a4-6795-4a24-b9c9-451efccf5af4", "historyId": "0e6237afc711dc95be5d6900cbb7e631", "testCaseId": "b1928a7174b0d14afd7479ec3844ea33", "fullName": "scripts.test01_mp_login.TestMpLogin#test_mp_login", "labels": [{"name": "parentSuite", "value": "scripts"}, {"name": "suite", "value": "test01_mp_login"}, {"name": "subSuite", "value": "TestMpLogin"}, {"name": "host", "value": "DESKTOP-41H0IB1"}, {"name": "thread", "value": "10336-MainThread"}, {"name": "framework", "value": "pytest"}, {"name": "language", "value": "cpython3"}, {"name": "package", "value": "scripts.test01_mp_login"}]}